Workbook

Sheet JP
A1: _id | B1: verified | C1: deviceId | D1: userId | E1: locale | F1: code | G1: channel | H1: action | I1: createdAt | J1: updatedAt | K1: __v
A2: 68aba786d9e956252c240bb9 | B2: FALSE | C2: 6dba1bebf019f6a7 | D2: okta_ca35e3e9-2e78-471e-935a-1ab53c4b6edf | E2: ja-JP | F2: 287129 | G2: mobile | H2: register | I2: 2025-08-25T00:00:06.360Z | J2: 2025-08-25T00:00:06.360Z | K2: 0
A3: 68aba7c4a3d5d92900d02618 | B3: FALSE | C3: 6dba1bebf019f6a7 | D3: okta_ca35e3e9-2e78-471e-935a-1ab53c4b6edf | E3: ja-JP | F3: 633582 | G3: mobile | H3: register | I3: 2025-08-25T00:01:08.331Z | J3: 2025-08-25T00:01:08.331Z | K3: 0
A4: 68aba7cfa3d5d92900d02637 | B4: FALSE | C4: E65D9290-F6AE-4148-A5AA-624795BE2D36 | D4: okta_3a4ad3e0-93a4-470f-a8ad-619b9822e448 | E4: ja-JP | F4: 122672 | G4: mobile | H4: register | I4: 2025-08-25T00:01:19.886Z | J4: 2025-08-25T00:01:19.886Z | K4: 0
A5: 68aba7e3d9e956252c240cc0 | B5: FALSE | C5: 7BF1E6FB-F3EF-4DB5-A457-19F208A37863 | D5: JR173LWJONNK | E5: ja-JP | F5: 890190 | G5: mobile | H5: login | I5: 2025-08-25T00:01:39.561Z | J5: 2025-08-25T00:01:39.561Z | K5: 0
A6: 68aba854d9e956252c240dfa | B6: FALSE | C6: 61d6e19f4b9beec8 | D6: PC23807632 | E6: ja-JP | F6: 528481 | G6: mobile | H6: login | I6: 2025-08-25T00:03:32.181Z | J6: 2025-08-25T00:03:32.181Z | K6: 0
A7: 68aba96dd9e956252c2410da | B7: FALSE | C7: A6EE8915-4E7B-4178-B913-D9F5253F28B8 | D7: JR172E7Z48GM | E7: ja-JP | F7: 463418 | G7: mobile | H7: login | I7: 2025-08-25T00:08:13.634Z | J7: 2025-08-25T00:08:13.634Z | K7: 0
A8: 68aba98ba3d5d92900d02ab6 | B8: FALSE | C8: a7575f9904531fb4 | D8: okta_bcc290e6-b94a-4b50-a974-b67507c5884a | E8: ja-JP | F8: 628065 | G8: mobile | H8: register | I8: 2025-08-25T00:08:43.850Z | J8: 2025-08-25T00:08:43.850Z | K8: 0
A9: 68aba9abd9e956252c241193 | B9: FALSE | C9: B041C4DC-C78B-41B2-91A2-EB56D0F793B2 | D9: JR175PUXOZOH | E9: ja-JP | F9: 516178 | G9: mobile | H9: login | I9: 2025-08-25T00:09:15.679Z | J9: 2025-08-25T00:09:15.679Z | K9: 0
A10: 68aba9eaa3d5d92900d02b7d | B10: FALSE | C10: F2249C67-EC3C-4085-B347-0FB9ACFACF82 | D10: okta_ce198a13-ea6c-4570-84b5-92f9dbb7120b | E10: ja-JP | F10: 482261 | G10: mobile | H10: register | I10: 2025-08-25T00:10:18.321Z | J10: 2025-08-25T00:10:18.321Z | K10: 0
A11: 68abaa4da3d5d92900d02c5d | B11: FALSE | C11: 202F909E-ED91-40D9-A381-DDA66689F92C | D11: JR175OSBRI3J | E11: ja-JP | F11: 508626 | G11: mobile | H11: login | I11: 2025-08-25T00:11:57.995Z | J11: 2025-08-25T00:11:57.995Z | K11: 0
A12: 68abab10a3d5d92900d02e64 | B12: FALSE | C12: 1F343A59-2294-46C4-ADC4-EEBDCFAB999B | D12: JR173320ZP96 | E12: ja-JP | F12: 607623 | G12: mobile | H12: login | I12: 2025-08-25T00:15:12.494Z | J12: 2025-08-25T00:15:12.494Z | K12: 0
A13: 68ababf0a3d5d92900d0305b | B13: FALSE | C13: 5AA88F4A-63EF-4534-A326-49FBEA3427D1 | D13: okta_7b5a064e-4b0b-461e-a2ee-d346ccb05881 | E13: ja-JP | F13: 639701 | G13: mobile | H13: register | I13: 2025-08-25T00:18:56.145Z | J13: 2025-08-25T00:18:56.145Z | K13: 0
... A46: 68abb3c4d9e956252c242bd4 | B46: FALSE | C46: 43B7D0B9-0E0C-4C42-922E-4C2A85EAF9AB | D46: okta_0509f438-905d-4cf2-ab66-0a71f45400bd | E46: ja-JP | F46: 505580 | G46: mobile | H46: register | I46: 2025-08-25T00:52:20.075Z | J46: 2025-08-25T00:52:20.075Z | K46: 0
A47: 68abb475a3d5d92900d046d2 | B47: FALSE | C47: 7016D51E-1534-4AA1-83C5-01082FCF3EAF | D47: 14138501 | E47: ja-JP | F47: 480641 | G47: mobile | H47: login | I47: 2025-08-25T00:55:17.317Z | J47: 2025-08-25T00:55:17.317Z | K47: 0
A48: 68abb494ffcf7f18507c5ded | B48: FALSE | C48: DCA80582-E2F1-419E-96D9-D210172899EE | D48: okta_dac48afb-a9b1-4c55-9296-9cb7d22cc6c8 | E48: ja-JP | F48: 710707 | G48: mobile | H48: register | I48: 2025-08-25T00:55:48.963Z | J48: 2025-08-25T00:55:48.963Z | K48: 0
A49: 68abb4d3a3d5d92900d047ae | B49: FALSE | C49: EB5DE8B0-BA76-4DCF-A9C0-CEB1EE0D429A | D49: okta_5669a8a9-287a-4339-b2dc-7982bcde3833 | E49: ja-JP | F49: 274601 | G49: mobile | H49: register | I49: 2025-08-25T00:56:51.538Z | J49: 2025-08-25T00:56:51.538Z | K49: 0
A50: 68abb4f3ffcf7f18507c5eb0 | B50: FALSE | C50: 55C47BE1-789A-49E1-9585-42F508B96165 | D50: okta_4545a434-5369-4317-a9e1-619926333917 | E50: ja-JP | F50: 551018 | G50: mobile | H50: register | I50: 2025-08-25T00:57:23.693Z | J50: 2025-08-25T00:57:23.693Z | K50: 0
A51: 68abb536a3d5d92900d0488d | B51: FALSE | C51: 6A71DE89-9FF7-4543-814B-9E9846C48E5D | D51: JR175F0GMXGM | E51: ja-JP | F51: 860705 | G51: mobile | H51: login | I51: 2025-08-25T00:58:30.470Z | J51: 2025-08-25T00:58:30.470Z | K51: 0
A52: 68abb53bffcf7f18507c5f6e | B52: FALSE | C52: 55C47BE1-789A-49E1-9585-42F508B96165 | D52: okta_4545a434-5369-4317-a9e1-619926333917 | E52: ja-JP | F52: 497286 | G52: mobile | H52: register | I52: 2025-08-25T00:58:35.946Z | J52: 2025-08-25T00:58:35.946Z | K52: 0
A53: 68abb577ffcf7f18507c6024 | B53: FALSE | C53: 440252A7-D93F-41A8-B710-A6C56AAF59C6 | D53: JR175T7KPD23 | E53: ja-JP | F53: 334164 | G53: mobile | H53: login | I53: 2025-08-25T00:59:35.398Z | J53: 2025-08-25T00:59:35.398Z | K53: 0
A54: 68abb614ffcf7f18507c61a3 | B54: FALSE | C54: B22DE170-43CE-4B5D-BCC2-540087237C69 | D54: okta_28e2138b-db73-4187-9286-53e2f6f1c034 | E54: ja-JP | F54: 944296 | G54: mobile | H54: register | I54: 2025-08-25T01:02:12.248Z | J54: 2025-08-25T01:02:12.248Z | K54: 0
A55: 68abb652a3d5d92900d04b89 | B55: FALSE | C55: C5F977E8-B8F5-454D-858A-8D465B58E073 | D55: okta_6a07ede2-ef1b-4956-b1f4-79d483a4cde7 | E55: ja-JP | F55: 710790 | G55: mobile | H55: register | I55: 2025-08-25T01:03:14.945Z | J55: 2025-08-25T01:03:14.945Z | K55: 0
A56: 68abb6b8ffcf7f18507c6343 | B56: FALSE | C56: 2ddc1cc5e75695fc | D56: okta_3df0dc17-059c-4a50-8c49-86b5cd2f985d | E56: ja-JP | F56: 443732 | G56: mobile | H56: register | I56: 2025-08-25T01:04:56.434Z | J56: 2025-08-25T01:04:56.434Z | K56: 0
A57: 68abb70dd9e956252c243439 | B57: FALSE | C57: CC7255E0-8D2E-440A-887E-8A706EAAD2AD | D57: okta_3c3997ac-b183-4915-8d09-73b391cb7a28 | E57: ja-JP | F57: 130611 | G57: mobile | H57: register | I57: 2025-08-25T01:06:21.133Z | J57: 2025-08-25T01:06:21.133Z | K57: 0
A58: 68abb725d9e956252c24347c | B58: FALSE | C58: 229A6221-725F-44F2-9116-4A6B8E1D1FDF | D58: JR1725BPB2MQ | E58: ja-JP | F58: 484305 | G58: mobile | H58: login | I58: 2025-08-25T01:06:45.210Z | J58: 2025-08-25T01:06:45.210Z | K58: 0
A59: 68abb73fa3d5d92900d04e13 | B59: FALSE | C59: FB3CE24A-D5BE-4670-9B42-783838772CE7 | D59: okta_87a9e89a-ce5a-4378-9a3c-4393a1851acf | E59: ja-JP | F59: 853379 | G59: mobile | H59: register | I59: 2025-08-25T01:07:11.092Z | J59: 2025-08-25T01:07:11.092Z | K59: 0
... A137: 68abc66407920c1ecc36b488 | B137: FALSE | C137: 3D40B80A-7AA1-4801-A9EF-9E052249B6AA | D137: JR172ZEI6KET | E137: ja-JP | F137: 113725 | G137: mobile | H137: login | I137: 2025-08-25T02:11:48.037Z | J137: 2025-08-25T02:11:48.037Z | K137: 0
A138: 68abc667201d482860090ae0 | B138: FALSE | C138: d1388622a28c7c70 | D138: 15193683 | E138: ja-JP | F138: 872634 | G138: mobile | H138: login | I138: 2025-08-25T02:11:51.912Z | J138: 2025-08-25T02:11:51.912Z | K138: 0
A139: 68abc68607920c1ecc36b4d7 | B139: FALSE | C139: e5b7c55530a07deb | D139: JR174N9V9IA2 | E139: ja-JP | F139: 152121 | G139: mobile | H139: login | I139: 2025-08-25T02:12:22.616Z | J139: 2025-08-25T02:12:22.616Z | K139: 0
A140: 68abc69bd9e956252c245b45 | B140: FALSE | C140: 7413AE71-DE16-479D-93BE-C6EAEB530127 | D140: JR17DEOEH6C | E140: ja-JP | F140: 529372 | G140: mobile | H140: login | I140: 2025-08-25T02:12:43.236Z | J140: 2025-08-25T02:12:43.236Z | K140: 0
A141: 68abc6f7d9e956252c245c24 | B141: FALSE | C141: 54711000-BF11-4EEF-B749-D21220EFB50E | D141: JR1754OTTP27 | E141: ja-JP | F141: 730039 | G141: mobile | H141: changeEmail | I141: 2025-08-25T02:14:15.799Z | J141: 2025-08-25T02:14:15.799Z | K141: 0
A142: 68abc6fc201d482860090c48 | B142: FALSE | C142: 54711000-BF11-4EEF-B749-D21220EFB50E | D142: JR1754OTTP27 | E142: ja-JP | F142: 535869 | G142: mobile | H142: changeEmail | I142: 2025-08-25T02:14:20.305Z | J142: 2025-08-25T02:14:20.305Z | K142: 0
A143: 68abc6ff201d482860090c54 | B143: FALSE | C143: 54711000-BF11-4EEF-B749-D21220EFB50E | D143: JR1754OTTP27 | E143: ja-JP | F143: 255226 | G143: mobile | H143: changeEmail | I143: 2025-08-25T02:14:23.957Z | J143: 2025-08-25T02:14:23.957Z | K143: 0
A144: 68abc723201d482860090c8d | B144: FALSE | C144: aa6b2351318047c0 | D144: JR171FARJ0FQ | E144: ja-JP | F144: 267630 | G144: mobile | H144: login | I144: 2025-08-25T02:14:59.711Z | J144: 2025-08-25T02:14:59.711Z | K144: 0
A145: 68abc7bb07920c1ecc36b771 | B145: FALSE | C145: 5A90B2A3-97E4-4191-BA5E-3E03C598E0B4 | D145: JR17F1XDIPR | E145: ja-JP | F145: 962543 | G145: mobile | H145: login | I145: 2025-08-25T02:17:32.000Z | J145: 2025-08-25T02:17:32.000Z | K145: 0
A146: 68abc7ff201d482860090e3e | B146: FALSE | C146: 3D40B80A-7AA1-4801-A9EF-9E052249B6AA | D146: JR172ZEI6KET | E146: ja-JP | F146: 144614 | G146: mobile | H146: login | I146: 2025-08-25T02:18:39.642Z | J146: 2025-08-25T02:18:39.642Z | K146: 0
A147: 68abc81b07920c1ecc36b842 | B147: FALSE | C147: 3D94449B-5AB2-4EE6-A234-0C4499065A70 | D147: okta_8d856202-e142-4077-a9fd-f64c8eb97aec | E147: ja-JP | F147: 695598 | G147: mobile | H147: register | I147: 2025-08-25T02:19:07.642Z | J147: 2025-08-25T02:19:07.642Z | K147: 0
A148: 68abc850201d482860090eed | B148: FALSE | C148: 07E29ECC-01D1-464C-8FC0-3BE94F17C4E1 | D148: okta_d4526e97-1a72-4970-b4a6-a97430f0f068 | E148: ja-JP | F148: 250518 | G148: mobile | H148: register | I148: 2025-08-25T02:20:00.946Z | J148: 2025-08-25T02:20:00.946Z | K148: 0
A149: 68abc8d3201d482860090fe5 | B149: FALSE | C149: CEFC57CA-3D8A-48DD-875F-F2BFCEF9CF7A | D149: okta_b0adb52a-5e00-46ec-bbbc-10f95129465f | E149: ja-JP | F149: 778054 | G149: mobile | H149: register | I149: 2025-08-25T02:22:11.824Z | J149: 2025-08-25T02:22:11.824Z | K149: 0
...

Sheet IN
A1: _id | B1: verified | C1: deviceId | D1: userId | E1: locale | F1: code | G1: channel | H1: action | I1: createdAt | J1: updatedAt | K1: __v
A2: 68abb96aa3d5d92900d053d8 | B2: FALSE | C2: bd1acbc44a1c827a | D2: okta_8539b5c7-f922-4581-8203-db9dc1f3b992 | E2: en-IN | F2: 361845 | G2: mobile | H2: login | I2: 2025-08-25T01:16:26.464Z | J2: 2025-08-25T01:16:26.464Z | K2: 0
A3: 68abbfa5a3d5d92900d06393 | B3: FALSE | C3: 5927b5bc7c1bce1a | D3: okta_16aacec7-d78e-4e76-a718-7370932f18a0 | E3: en-IN | F3: 556016 | G3: mobile | H3: register | I3: 2025-08-25T01:43:01.961Z | J3: 2025-08-25T01:43:01.961Z | K3: 0
A4: 68abbfd0ffcf7f18507c7ad6 | B4: TRUE | C4: 5927b5bc7c1bce1a | D4: okta_16aacec7-d78e-4e76-a718-7370932f18a0 | E4: en-IN | F4: 479261 | G4: mobile | H4: changeEmail | I4: 2025-08-25T01:43:44.116Z | J4: 2025-08-25T01:44:24.847Z | K4: 0
A5: 68abbfffffcf7f18507c7b2f | B5: FALSE | C5: 5927b5bc7c1bce1a | D5: okta_16aacec7-d78e-4e76-a718-7370932f18a0 | E5: en-IN | F5: 272391 | G5: mobile | H5: register | I5: 2025-08-25T01:44:31.804Z | J5: 2025-08-25T01:44:31.804Z | K5: 0
A6: 68abc06fffcf7f18507c7c2b | B6: FALSE | C6: f7e3db862a5586b4 | D6: okta_f217b177-debe-4452-9c6d-b195720c6f16 | E6: en-IN | F6: 940369 | G6: mobile | H6: register | I6: 2025-08-25T01:46:23.833Z | J6: 2025-08-25T01:46:23.833Z | K6: 0
A7: 68abc10bffcf7f18507c7d76 | B7: FALSE | C7: f7e3db862a5586b4 | D7: okta_f217b177-debe-4452-9c6d-b195720c6f16 | E7: en-IN | F7: 544953 | G7: mobile | H7: register | I7: 2025-08-25T01:48:59.289Z | J7: 2025-08-25T01:48:59.289Z | K7: 0
A8: 68abc137ffcf7f18507c7de8 | B8: FALSE | C8: f7e3db862a5586b4 | D8: okta_f217b177-debe-4452-9c6d-b195720c6f16 | E8: en-IN | F8: 152243 | G8: mobile | H8: register | I8: 2025-08-25T01:49:43.817Z | J8: 2025-08-25T01:49:43.817Z | K8: 0
A9: 68abc1f9d9e956252c244fbd | B9: FALSE | C9: 3db3caf434bdb647 | D9: okta_3671c57e-0a9d-401d-8571-76a893ee3c8f | E9: en-IN | F9: 277669 | G9: mobile | H9: register | I9: 2025-08-25T01:52:57.489Z | J9: 2025-08-25T01:52:57.489Z | K9: 0
A10: 68abc2beffcf7f18507c81a0 | B10: FALSE | C10: ce44ff6f11176821 | D10: okta_3be28b5e-b8e9-47ed-ada8-9753f8c5130b | E10: en-IN | F10: 607111 | G10: mobile | H10: register | I10: 2025-08-25T01:56:14.108Z | J10: 2025-08-25T01:56:14.108Z | K10: 0
A11: 68abc30effcf7f18507c827d | B11: FALSE | C11: 0e57aa2f92b68932 | D11: okta_e5e449c1-d6d8-4be3-85e3-3d75e7e3a4ea | E11: en-IN | F11: 709965 | G11: mobile | H11: register | I11: 2025-08-25T01:57:34.295Z | J11: 2025-08-25T01:57:34.295Z | K11: 0
A12: 68abc329d9e956252c24529b | B12: FALSE | C12: 0e57aa2f92b68932 | D12: okta_e5e449c1-d6d8-4be3-85e3-3d75e7e3a4ea | E12: en-IN | F12: 765400 | G12: mobile | H12: register | I12: 2025-08-25T01:58:01.994Z | J12: 2025-08-25T01:58:01.994Z | K12: 0
A13: 68abc5ce07920c1ecc36b347 | B13: FALSE | C13: 325ec800a40405c4 | D13: okta_e844cdfa-ef69-4ba5-99d6-25535563f4d5 | E13: en-IN | F13: 876607 | G13: mobile | H13: login | I13: 2025-08-25T02:09:18.794Z | J13: 2025-08-25T02:09:18.794Z | K13: 0
... A1395: 68ae2504a1c6701f384fd631 | B1395: FALSE | C1395: 9fb9b3ee7e78aecc | D1395: okta_2df9211e-ca34-4004-a9fb-2710e5fbe288 | E1395: en-IN | F1395: 368774 | G1395: mobile | H1395: changeEmail | I1395: 2025-08-26T21:20:04.876Z | J1395: 2025-08-26T21:20:04.876Z | K1395: 0

Sheet PT
A1: _id | B1: verified | C1: deviceId | D1: userId | E1: locale | F1: code | G1: channel | H1: action | I1: createdAt | J1: updatedAt | K1: __v
A2: 68abb27e422d7e23947fe19e | B2: FALSE | C2: f53877261d2e5403 | D2: JR8n4XXXJJSP | E2: pt-PT | F2: 908543 | G2: mobile | H2: register | I2: 2025-08-25T00:46:54.342Z | J2: 2025-08-25T00:46:54.342Z | K2: 0
A3: 68abb2ad624c20275cf7a096 | B3: FALSE | C3: f53877261d2e5403 | D3: JR8n4XXXJJSP | E3: pt-PT | F3: 261565 | G3: mobile | H3: register | I3: 2025-08-25T00:47:41.949Z | J3: 2025-08-25T00:47:41.949Z | K3: 0
A4: 68abb2bcfbc1292488a6b28c | B4: FALSE | C4: f53877261d2e5403 | D4: JR8n4XXXJJSP | E4: pt-PT | F4: 892926 | G4: mobile | H4: changeEmail | I4: 2025-08-25T00:47:56.567Z | J4: 2025-08-25T00:47:56.567Z | K4: 0
A5: 68abf3ab41f00a18f4a56a9a | B5: FALSE | C5: bd9319b4e3caa3cf | D5: okta_1771a4b8-662f-4df1-b954-2fc5e9cbdfae | E5: pt-PT | F5: 269943 | G5: mobile | H5: login | I5: 2025-08-25T05:24:59.540Z | J5: 2025-08-25T05:24:59.540Z | K5: 0
A6: 68abf3b07a5643310ceddf0a | B6: FALSE | C6: bd9319b4e3caa3cf | D6: okta_1771a4b8-662f-4df1-b954-2fc5e9cbdfae | E6: pt-PT | F6: 270592 | G6: mobile | H6: login | I6: 2025-08-25T05:25:04.333Z | J6: 2025-08-25T05:25:04.333Z | K6: 0
A7: 68abf55b624c20275cf7b3da | B7: FALSE | C7: bd9319b4e3caa3cf | D7: okta_1771a4b8-662f-4df1-b954-2fc5e9cbdfae | E7: pt-PT | F7: 105518 | G7: mobile | H7: login | I7: 2025-08-25T05:32:11.158Z | J7: 2025-08-25T05:32:11.158Z | K7: 0
A8: 68abfd0646f927240cf1afce | B8: FALSE | C8: 23A5DADA-8A67-4BC6-BC2F-1A9E2AEF34E6 | D8: JR8n5BCF4QF6 | E8: pt-PT | F8: 609416 | G8: mobile | H8: login | I8: 2025-08-25T06:04:54.047Z | J8: 2025-08-25T06:04:54.047Z | K8: 0
A9: 68ac04d38245ae1a8c02b501 | B9: FALSE | C9: 78CBDB34-3A18-4A22-920A-1AF70750852A | D9: JR8n31O6KLVO | E9: pt-PT | F9: 948273 | G9: mobile | H9: login | I9: 2025-08-25T06:38:11.600Z | J9: 2025-08-25T06:38:11.600Z | K9: 0
A10: 68ac0a384ac02b1f80751edb | B10: FALSE | C10: A702B705-9636-4A05-B4B0-BA91055746CB | D10: okta_e4fa1544-d3a7-49c6-ac60-92dab611f79f | E10: pt-PT | F10: 941790 | G10: mobile | H10: login | I10: 2025-08-25T07:01:12.992Z | J10: 2025-08-25T07:01:12.992Z | K10: 0
A11: 68ac0addee7d08264453111b | B11: FALSE | C11: 98B97565-10BC-4602-98B0-B324AC2C4C1F | D11: okta_31f7035b-feb1-402e-8e83-88301cd00f3a | E11: pt-PT | F11: 354204 | G11: mobile | H11: login | I11: 2025-08-25T07:03:57.969Z | J11: 2025-08-25T07:03:57.969Z | K11: 0
A12: 68ac0b37ee7d082644531242 | B12: FALSE | C12: 82626CAF-74B4-4E4D-837C-9C1DB377698B | D12: okta_78f4edf1-17b5-4d93-8f58-fb8402bc1b27 | E12: pt-PT | F12: 880578 | G12: mobile | H12: login | I12: 2025-08-25T07:05:27.539Z | J12: 2025-08-25T07:05:27.539Z | K12: 0
A13: 68ac0e27ee7d082644531b77 | B13: FALSE | C13: bde75afeb0a947b1 | D13: JR8n5GBBNW5V | E13: pt-PT | F13: 997522 | G13: mobile | H13: login | I13: 2025-08-25T07:17:59.649Z | J13: 2025-08-25T07:17:59.649Z | K13: 0
... A367: 68ae02bdbcb17d2104363c38 | B367: FALSE | C367: 96d69201fdbb2b83 | D367: JR8n3A0BKGG6 | E367: pt-PT | F367: 919461 | G367: mobile | H367: login | I367: 2025-08-26T18:53:49.197Z | J367: 2025-08-26T18:53:49.197Z | K367: 0
A368: 68ae03e0c0be5c2f30264d9d | B368: FALSE | C368: f92bfaef9ea48d43 | D368: 2546767 | E368: pt-PT | F368: 283565 | G368: mobile | H368: login | I368: 2025-08-26T18:58:40.821Z | J368: 2025-08-26T18:58:40.821Z | K368: 0
A369: 68ae058fc0be5c2f3026537b | B369: FALSE | C369: 76341d42dbc0f501 | D369: JR8n459X9KUF | E369: pt-PT | F369: 951430 | G369: mobile | H369: login | I369: 2025-08-26T19:05:51.672Z | J369: 2025-08-26T19:05:51.672Z | K369: 0
A370: 68ae05ce82f7e81544136e85 | B370: FALSE | C370: 843B5C25-6352-4139-BC96-17214AE47016 | D370: okta_36938ec6-378c-4d59-8f73-75f19e1f5140 | E370: pt-PT | F370: 913701 | G370: mobile | H370: login | I370: 2025-08-26T19:06:54.510Z | J370: 2025-08-26T19:06:54.510Z | K370: 0
A371: 68ae066d82f7e81544137084 | B371: FALSE | C371: 29D16CAC-277E-40AF-94C8-129518AE3FD6 | D371: JR8n6G2RS1KH | E371: pt-PT | F371: 905116 | G371: mobile | H371: login | I371: 2025-08-26T19:09:33.919Z | J371: 2025-08-26T19:09:33.919Z | K371: 0
A372: 68ae074f14afab21cc320dd3 | B372: FALSE | C372: 871a4d6e26e5b988 | D372: okta_2cf1e3e1-3fd6-403a-ae6f-9897ddcf9a55 | E372: pt-PT | F372: 514463 | G372: mobile | H372: login | I372: 2025-08-26T19:13:19.101Z | J372: 2025-08-26T19:13:19.101Z | K372: 0
A373: 68ae0fae9971ae292c4db284 | B373: FALSE | C373: E1D28495-034A-45A2-A1FC-14579A104B6B | D373: okta_d1dbe691-5c68-4b25-be27-f62705b0e216 | E373: pt-PT | F373: 365232 | G373: mobile | H373: register | I373: 2025-08-26T19:49:02.758Z | J373: 2025-08-26T19:49:02.758Z | K373: 0
A374: 68ae102abb7c361e6c166599 | B374: FALSE | C374: bb18be8fd2d0e0a1 | D374: okta_36372a11-3bb2-4659-8e86-904ffb619c07 | E374: pt-PT | F374: 473543 | G374: mobile | H374: register | I374: 2025-08-26T19:51:06.955Z | J374: 2025-08-26T19:51:06.955Z | K374: 0
A375: 68ae10ea9971ae292c4db606 | B375: FALSE | C375: EB75F9B5-AE3A-4409-A5EB-19C306394AB8 | D375: JR8n3OMV8GN0 | E375: pt-PT | F375: 848694 | G375: mobile | H375: login | I375: 2025-08-26T19:54:18.502Z | J375: 2025-08-26T19:54:18.502Z | K375: 0
A376: 68ae1171fde0562eb4c52929 | B376: FALSE | C376: E828AF4C-5936-4164-9A2B-0C011DBC69D3 | D376: JR8n1R22ELRS | E376: pt-PT | F376: 444606 | G376: mobile | H376: login | I376: 2025-08-26T19:56:33.938Z | J376: 2025-08-26T19:56:33.938Z | K376: 0
A377: 68ae1416393bd62944add584 | B377: FALSE | C377: a14e3ab8144023ce | D377: okta_1d986d6c-7302-48c3-913d-667afeee4f17 | E377: pt-PT | F377: 173517 | G377: mobile | H377: login | I377: 2025-08-26T20:07:50.803Z | J377: 2025-08-26T20:07:50.803Z | K377: 0
A378: 68ae161dfde0562eb4c535a5 | B378: FALSE | C378: 5291665A-0633-4890-AA40-11C695846DA7 | D378: okta_957896d3-5cd9-4b08-be39-c6cdfe24d6f7 | E378: pt-PT | F378: 935871 | G378: mobile | H378: register | I378: 2025-08-26T20:16:29.614Z | J378: 2025-08-26T20:16:29.614Z | K378: 0
A379: 68ae16e601cc8f26c41631d3 | B379: FALSE | C379: bd80200754be228c | D379: okta_6a547863-d447-478b-9b57-c723b6082a19 | E379: pt-PT | F379: 763264 | G379: mobile | H379: login | I379: 2025-08-26T20:19:50.890Z | J379: 2025-08-26T20:19:50.890Z | K379: 0
A380: 68ae182ca769cd12b484a5ce | B380: FALSE | C380: 4e4769ad26ab966c | D380: JR8n34NDV0SP | E380: pt-PT | F380: 884398 | G380: mobile | H380: login | I380: 2025-08-26T20:25:16.285Z | J380: 2025-08-26T20:25:16.285Z | K380: 0
... A387: 68ae1aea01cc8f26c4163b57 | B387: FALSE | C387: bd9319b4e3caa3cf | D387: okta_1771a4b8-662f-4df1-b954-2fc5e9cbdfae | E387: pt-PT | F387: 669266 | G387: mobile | H387: login | I387: 2025-08-26T20:36:58.010Z | J387: 2025-08-26T20:36:58.010Z | K387: 0
A388: 68ae1d7583df01214c9c0cf9 | B388: FALSE | C388: 06726841179846d4 | D388: 2805111 | E388: pt-PT | F388: 923750 | G388: mobile | H388: login | I388: 2025-08-26T20:47:49.541Z | J388: 2025-08-26T20:47:49.541Z | K388: 0
A389: 68ae1dcf01cc8f26c41641ae | B389: FALSE | C389: 8228B5DA-62BA-4965-9415-3B0517EAF60D | D389: okta_d4be13f3-a65b-46bb-b7c8-bfbad136d38f | E389: pt-PT | F389: 747670 | G389: mobile | H389: login | I389: 2025-08-26T20:49:19.876Z | J389: 2025-08-26T20:49:19.876Z | K389: 0
A390: 68ae1e0483df01214c9c0e3e | B390: FALSE | C390: c8633ed207bba7c0 | D390: JR8n1KL7RER4 | E390: pt-PT | F390: 982361 | G390: mobile | H390: login | I390: 2025-08-26T20:50:12.050Z | J390: 2025-08-26T20:50:12.050Z | K390: 0
A391: 68ae1e2126e25b18dcca6186 | B391: FALSE | C391: 1acb0118ee2fed69 | D391: okta_f886eb7d-ac29-463d-a96c-21e65937349a | E391: pt-PT | F391: 270325 | G391: mobile | H391: login | I391: 2025-08-26T20:50:41.610Z | J391: 2025-08-26T20:50:41.610Z | K391: 0
A392: 68ae1e4583df01214c9c0ed3 | B392: FALSE | C392: c8633ed207bba7c0 | D392: JR8n1KL7RER4 | E392: pt-PT | F392: 400388 | G392: mobile | H392: login | I392: 2025-08-26T20:51:17.375Z | J392: 2025-08-26T20:51:17.375Z | K392: 0
A393: 68ae224601cc8f26c41649f2 | B393: FALSE | C393: 79474D82-5434-4391-B912-1A056ABA459F | D393: okta_7355b13a-d477-4731-9236-a18304c56631 | E393: pt-PT | F393: 761406 | G393: mobile | H393: register | I393: 2025-08-26T21:08:22.568Z | J393: 2025-08-26T21:08:22.568Z | K393: 0
A394: 68ae22ce83df01214c9c172b | B394: FALSE | C394: 033c40a0788a78a9 | D394: okta_a4e58c67-7171-46b5-8c38-c7897116ce2b | E394: pt-PT | F394: 158658 | G394: mobile | H394: register | I394: 2025-08-26T21:10:38.648Z | J394: 2025-08-26T21:10:38.648Z | K394: 0
A395: 68ae24079166131624920d2a | B395: FALSE | C395: fbebd86f427c4edd | D395: okta_675d55b0-d159-44d2-9168-2f958f871451 | E395: pt-PT | F395: 218248 | G395: mobile | H395: register | I395: 2025-08-26T21:15:51.466Z | J395: 2025-08-26T21:15:51.466Z | K395: 0
A396: 68ae266826e25b18dcca6ff9 | B396: FALSE | C396: c6e1999ec09b3b86 | D396: JR8nEUJEM7H | E396: pt-PT | F396: 598279 | G396: mobile | H396: login | I396: 2025-08-26T21:26:00.979Z | J396: 2025-08-26T21:26:00.979Z | K396: 0
A397: 68ae266a26e25b18dcca6ffc | B397: FALSE | C397: 5D2C1586-7C1D-4F54-8C14-F40395AB019C | D397: PC31337812 | E397: pt-PT | F397: 787862 | G397: mobile | H397: login | I397: 2025-08-26T21:26:02.317Z | J397: 2025-08-26T21:26:02.317Z | K397: 0
A398: 68ae2c4ba769cd12b484c9b3 | B398: FALSE | C398: EC814458-3892-4C92-811A-DA1DF5F8677E | D398: okta_65105ad4-9b23-441c-9c02-b55437b26439 | E398: pt-PT | F398: 821323 | G398: mobile | H398: register | I398: 2025-08-26T21:51:07.661Z | J398: 2025-08-26T21:51:07.661Z | K398: 0
A399: 68ae3011a769cd12b484ce12 | B399: FALSE | C399: 0F1FD77E-4243-4ECB-87C6-5A55D4A1E014 | D399: JR8nKPMF6KS | E399: pt-PT | F399: 776317 | G399: mobile | H399: login | I399: 2025-08-26T22:07:13.675Z | J399: 2025-08-26T22:07:13.675Z | K399: 0
...

Sheet RO
A1: _id | B1: verified | C1: deviceId | D1: userId | E1: locale | F1: code | G1: channel | H1: action | I1: createdAt | J1: updatedAt | K1: __v
A2: 68abd3a84ac02b1f8074e1ba | B2: FALSE | C2: c58320d421df0f88 | D2: okta_7c6ca204-e2a2-4799-b50d-79f727323f71 | E2: ro-RO | F2: 242976 | G2: mobile | H2: register | I2: 2025-08-25T03:08:24.090Z | J2: 2025-08-25T03:08:24.090Z | K2: 0
A3: 68abe0fb422d7e23947fe6e7 | B3: FALSE | C3: D067CCA0-FF37-4758-845F-8867585E3528 | D3: okta_af52f552-54ec-47da-bf9b-9ccec59c74ce | E3: ro-RO | F3: 991106 | G3: mobile | H3: login | I3: 2025-08-25T04:05:15.626Z | J3: 2025-08-25T04:05:15.626Z | K3: 0
A4: 68abe82241f00a18f4a560fd | B4: FALSE | C4: dbee50e069225fa2 | D4: JRam6U2BTYO1 | E4: ro-RO | F4: 241659 | G4: mobile | H4: login | I4: 2025-08-25T04:35:46.081Z | J4: 2025-08-25T04:35:46.081Z | K4: 0
A5: 68abef297a5643310cedda05 | B5: FALSE | C5: E48589CC-03B1-407D-A05E-572D524EA6F8 | D5: JRam4G6B2N4B | E5: ro-RO | F5: 884782 | G5: mobile | H5: login | I5: 2025-08-25T05:05:45.004Z | J5: 2025-08-25T05:05:45.004Z | K5: 0
A6: 68abef52422d7e23947fedcb | B6: FALSE | C6: 0b4a074c8c32d79c | D6: JRam4T71J97S | E6: ro-RO | F6: 340836 | G6: mobile | H6: login | I6: 2025-08-25T05:06:26.591Z | J6: 2025-08-25T05:06:26.591Z | K6: 0
A7: 68abf6d07a5643310cede335 | B7: FALSE | C7: F6115D5D-162E-4CB9-853B-664276282DFF | D7: okta_20f4955c-6a87-404e-8a48-759ce09b4bda | E7: ro-RO | F7: 539121 | G7: mobile | H7: register | I7: 2025-08-25T05:38:24.344Z | J7: 2025-08-25T05:38:24.344Z | K7: 0
A8: 68abf705422d7e23947ff718 | B8: FALSE | C8: F6115D5D-162E-4CB9-853B-664276282DFF | D8: okta_20f4955c-6a87-404e-8a48-759ce09b4bda | E8: ro-RO | F8: 916742 | G8: mobile | H8: register | I8: 2025-08-25T05:39:17.848Z | J8: 2025-08-25T05:39:17.848Z | K8: 0
A9: 68abf9096c7220216c4d4461 | B9: FALSE | C9: CC4F3585-9133-4BC7-9E86-8A9F5AF7BF13 | D9: okta_17391102-0480-4376-956d-b8b51c77c48f | E9: ro-RO | F9: 637031 | G9: mobile | H9: register | I9: 2025-08-25T05:47:53.670Z | J9: 2025-08-25T05:47:53.670Z | K9: 0
A10: 68abfdb59926793204421b35 | B10: FALSE | C10: 1bc5f162c0757ae5 | D10: JRam4TUZMNUI | E10: ro-RO | F10: 815926 | G10: mobile | H10: register | I10: 2025-08-25T06:07:49.676Z | J10: 2025-08-25T06:07:49.676Z | K10: 0
A11: 68abfdf89926793204421bbd | B11: FALSE | C11: 1bc5f162c0757ae5 | D11: JRam4TUZMNUI | E11: ro-RO | F11: 354008 | G11: mobile | H11: register | I11: 2025-08-25T06:08:56.939Z | J11: 2025-08-25T06:08:56.939Z | K11: 0
A12: 68abfe026c7220216c4d4da3 | B12: FALSE | C12: 250668c73b8617da | D12: okta_09f79526-fd10-4aa4-9f32-c32b4f7d1bba | E12: ro-RO | F12: 754879 | G12: mobile | H12: login | I12: 2025-08-25T06:09:06.070Z | J12: 2025-08-25T06:09:06.070Z | K12: 0
A13: 68ac00126c7220216c4d51d1 | B13: FALSE | C13: 9f8d53eb9f7c3919 | D13: okta_cfcc49d3-ee66-4d02-b132-544076c4d543 | E13: ro-RO | F13: 168261 | G13: mobile | H13: register | I13: 2025-08-25T06:17:54.295Z | J13: 2025-08-25T06:17:54.295Z | K13: 0
... A426: 68ae40617e4dc12eb8bd96ca | B426: FALSE | C426: f33166f77563d226 | D426: okta_8cfbc63e-b943-4996-a48d-abf888556517 | E426: ro-RO | F426: 705033 | G426: mobile | H426: login | I426: 2025-08-26T23:16:49.698Z | J426: 2025-08-26T23:16:49.698Z | K426: 0

Sheet braze_all
A1: user_id | B1: exposed_timestamp | C1: backend_createdat_ts | D1: sent_timestamp | E1: delivered_timestamp | F1: bounced_timestamp | G1: country_code | H1: sent_earlier_than_exposed | I1: delivered_earlier_than_exposed | J1: bounced_earlier_than_exposed | K1: exposed_to_sent_sec | L1: sent_to_delivered_sec | M1: exposed_to_delivered_sec | N1: COMMENTS
A2: JR174UU7RR15 | B2: 2025-08-25 07:47:40.979000 UTC | C2: 2025-08-25T07:47:40.497Z | D2: 2025-08-26 13:23:57.000000 UTC | E2: 2025-08-26 13:24:01.000000 UTC | G2: jp | H2: FALSE | I2: FALSE | K2: 106576.02 | L2: 4 | M2: 106580.02
A3: JR174JG5KLXE | B3: 2025-08-26 19:56:40.313000 UTC | C3: 2025-08-26T20:00:49.969Z | D3: 2025-08-26 20:00:56.000000 UTC | E3: 2025-08-26 20:00:57.000000 UTC | G3: jp | H3: FALSE | I3: FALSE | K3: 255.687 | L3: 1 | M3: 256.687
A4: okta_098fb5b7-68ea-4176-beaf-75bd83829737 | B4: 2025-08-25 12:31:50.695000 UTC | C4: 2025-08-25T12:31:50.077Z | D4: 2025-08-25 12:32:50.000000 UTC | E4: 2025-08-25 12:32:51.000000 UTC | G4: jp | H4: FALSE | I4: FALSE | K4: 59.305 | L4: 1 | M4: 60.305
A5: JR173IGHW8OY | B5: 2025-08-25 21:15:16.005000 UTC | C5: 2025-08-25T21:15:15.886Z | D5: 2025-08-25 21:16:15.000000 UTC | E5: 2025-08-25 21:16:20.000000 UTC | G5: jp | H5: FALSE | I5: FALSE | K5: 58.995 | L5: 5 | M5: 63.995
A6: JR176LTRTZDD | B6: 2025-08-26 08:17:44.287000 UTC | C6: 2025-08-26T08:17:43.468Z | D6: 2025-08-26 08:18:36.000000 UTC | E6: 2025-08-26 08:18:38.000000 UTC | G6: jp | H6: FALSE | I6: FALSE | K6: 51.713 | L6: 2 | M6: 53.713
A7: okta_d818e952-158a-480a-a370-af2a2e11448b | B7: 2025-08-26 12:04:36.119000 UTC | C7: #N/A | D7: 2025-08-26 12:04:55.000000 UTC | E7: 2025-08-26 12:04:57.000000 UTC | G7: jp | H7: FALSE | I7: FALSE | K7: 18.881 | L7: 2 | M7: 20.881
A8: okta_01b05032-4daa-4ccc-91ec-2d93ed056728 | B8: 2025-08-26 18:34:40.657000 UTC | C8: 2025-08-26T18:34:49.774Z | D8: 2025-08-26 18:34:52.000000 UTC | E8: 2025-08-26 18:34:56.000000 UTC | G8: jp | H8: FALSE | I8: FALSE | K8: 11.343 | L8: 4 | M8: 15.343
A9: okta_20ee61de-8115-4c0f-94ea-ac414579790d | B9: 2025-08-26 05:29:38.908000 UTC | C9: 2025-08-26T05:29:47.600Z | D9: 2025-08-26 05:29:49.000000 UTC | E9: 2025-08-26 05:29:53.000000 UTC | G9: jp | H9: FALSE | I9: FALSE | K9: 10.092 | L9: 4 | M9: 14.092
A10: JR17IILVU99 | B10: 2025-08-25 13:00:33.932000 UTC | C10: 2025-08-25T13:00:33.374Z | D10: 2025-08-25 13:00:43.000000 UTC | E10: 2025-08-25 13:00:48.000000 UTC | G10: jp | H10: FALSE | I10: FALSE | K10: 9.068 | L10: 5 | M10: 14.068
A11: okta_0981c1ba-bace-4809-b8e6-cfe9bb571af7 | B11: 2025-08-25 12:51:38.492000 UTC | C11: 2025-08-25T12:51:37.912Z | D11: 2025-08-25 12:51:47.000000 UTC | E11: 2025-08-25 12:51:49.000000 UTC | G11: jp | H11: FALSE | I11: FALSE | K11: 8.508 | L11: 2 | M11: 10.508
A12: okta_800db731-13e7-4b5a-9f14-1f7e7037a111 | B12: 2025-08-26 12:44:49.552000 UTC | C12: 2025-08-26T12:44:55.570Z | D12: 2025-08-26 12:44:58.000000 UTC | E12: 2025-08-26 12:45:00.000000 UTC | G12: jp | H12: FALSE | I12: FALSE | K12: 8.448 | L12: 2 | M12: 10.448
A13: JR171C63M9K1 | B13: 2025-08-26 08:17:39.992000 UTC | C13: 2025-08-26T08:17:39.455Z | D13: 2025-08-26 08:17:48.000000 UTC | E13: 2025-08-26 08:17:57.000000 UTC | G13: jp | H13: FALSE | I13: FALSE | K13: 8.008 | L13: 9 | M13: 17.008
A14: PC31237449 | B14: 2025-08-26 22:16:26.612000 UTC | C14: 2025-08-26T22:16:26.569Z | D14: 2025-08-26 22:16:34.000000 UTC | E14: 2025-08-26 22:16:35.000000 UTC | G14: jp | H14: FALSE | I14: FALSE | K14: 7.388 | L14: 1 | M14: 8.388
A15: okta_5bb2ebfe-8e4b-4de6-892e-6d41444d977b | B15: 2025-08-26 22:47:01.040000 UTC | C15: 2025-08-26T22:47:00.484Z | D15: 2025-08-26 22:47:08.000000 UTC | E15: 2025-08-26 22:47:13.000000 UTC | G15: jp | H15: FALSE | I15: FALSE | K15: 6.96 | L15: 5 | M15: 11.96
A16: 104714598 | B16: 2025-08-25 13:46:59.248000 UTC | C16: 2025-08-25T13:46:59.199Z | G16: jp | N16: sees 2fa exposed, exceeds otp_request and2fa_multiple_codes_added
A17: okta_125d7060-5a9f-4839-8980-e644e60c744a | B17: 2025-08-26 23:53:08.335000 UTC | C17: 2025-08-26T23:53:07.973Z | D17: 2025-08-26 23:53:15.000000 UTC | E17: 2025-08-26 23:53:20.000000 UTC | G17: jp | H17: FALSE | I17: FALSE | K17: 6.665 | L17: 5 | M17: 11.665
A18: JR1767VG5QPA | B18: 2025-08-25 11:26:25.401000 UTC | C18: 2025-08-25T11:26:28.782Z | D18: 2025-08-25 11:26:32.000000 UTC | E18: 2025-08-25 11:26:34.000000 UTC | G18: jp | H18: FALSE | I18: FALSE | K18: 6.599 | L18: 2 | M18: 8.599
A19: okta_71c05c1c-e236-484d-bdad-37e820be4c58 | B19: 2025-08-26 15:04:42.458000 UTC | C19: 2025-08-26T15:04:42.061Z | D19: 2025-08-26 15:04:49.000000 UTC | E19: 2025-08-26 15:04:51.000000 UTC | G19: jp | H19: FALSE | I19: FALSE | K19: 6.542 | L19: 2 | M19: 8.542
A20: JR175F4KOQJJ | B20: 2025-08-26 14:46:09.467000 UTC | C20: 2025-08-26T14:46:09.219Z | D20: 2025-08-26 14:46:16.000000 UTC | E20: 2025-08-26 14:46:20.000000 UTC | G20: jp | H20: FALSE | I20: FALSE | K20: 6.533 | L20: 4 | M20: 10.533
A21: okta_02321cdd-2c02-4a4d-b534-d0f8b55bba67 | B21: 2025-08-25 13:06:12.752000 UTC | C21: 2025-08-25T13:06:12.269Z | D21: 2025-08-25 13:06:19.000000 UTC | E21: 2025-08-25 13:06:22.000000 UTC | G21: jp | H21: FALSE | I21: FALSE | K21: 6.248 | L21: 3 | M21: 9.248
A22: okta_8337a5e2-d2f6-4bb8-ab50-05de98cfe072 | B22: 2025-08-25 12:56:51.772000 UTC | C22: 2025-08-25T12:56:51.177Z | D22: 2025-08-25 12:56:58.000000 UTC | E22: 2025-08-25 12:57:01.000000 UTC | G22: jp | H22: FALSE | I22: FALSE | K22: 6.228 | L22: 3 | M22: 9.228
A23: PC32694804 | B23: 2025-08-25 13:06:23.964000 UTC | C23: 2025-08-25T13:06:23.325Z | D23: 2025-08-25 13:06:30.000000 UTC | E23: 2025-08-25 13:06:31.000000 UTC | G23: jp | H23: FALSE | I23: FALSE | K23: 6.036 | L23: 1 | M23: 7.036
A24: JR1758ILP0X3 | B24: 2025-08-25 11:01:03.125000 UTC | C24: 2025-08-25T11:01:02.687Z | D24: 2025-08-25 11:01:09.000000 UTC | E24: 2025-08-25 11:01:10.000000 UTC | G24: jp | H24: FALSE | I24: FALSE | K24: 5.875 | L24: 1 | M24: 6.875
A25: PC7215366 | B25: 2025-08-26 10:29:16.146000 UTC | C25: 2025-08-26T10:29:17.325Z | D25: 2025-08-26 10:29:22.000000 UTC | E25: 2025-08-26 10:29:25.000000 UTC | G25: jp | H25: FALSE | I25: FALSE | K25: 5.854 | L25: 3 | M25: 8.854
A26: PC32123296 | B26: 2025-08-26 13:47:00.518000 UTC | C26: 2025-08-26T13:46:59.957Z | D26: 2025-08-26 13:47:06.000000 UTC | E26: 2025-08-26 13:47:07.000000 UTC | G26: jp | H26: FALSE | I26: FALSE | K26: 5.482 | L26: 1 | M26: 6.482
A27: JR1742D9EBLQ | B27: 2025-08-25 14:06:56.694000 UTC | C27: 2025-08-25T14:06:55.993Z | D27: 2025-08-25 14:07:02.000000 UTC | E27: 2025-08-25 14:07:03.000000 UTC | G27: jp | H27: FALSE | I27: FALSE | K27: 5.306 | L27: 1 | M27: 6.306
A28: okta_74029db2-7b7c-4fc1-88cf-2c1e924ef8f0 | B28: 2025-08-26 02:40:53.996000 UTC | C28: 2025-08-26T02:40:53.423Z | D28: 2025-08-26 02:40:59.000000 UTC | E28: 2025-08-26 02:41:01.000000 UTC | G28: jp | H28: FALSE | I28: FALSE | K28: 5.004 | L28: 2 | M28: 7.004
A29: PC22672981 | B29: 2025-08-25 09:30:02.096000 UTC | C29: 2025-08-25T09:30:01.517Z | D29: 2025-08-25 09:30:07.000000 UTC | E29: 2025-08-25 09:30:08.000000 UTC | G29: jp | H29: FALSE | I29: FALSE | K29: 4.904 | L29: 1 | M29: 5.904
A30: okta_6112b141-486f-4586-aa5c-925a49649e53 | B30: 2025-08-25 07:36:15.106000 UTC | C30: 2025-08-25T07:36:14.544Z | D30: 2025-08-25 07:36:20.000000 UTC | F30: 2025-08-25 07:40:31.000000 UTC | G30: jp | H30: FALSE | J30: FALSE | K30: 4.894
A31: JR171P2XFCVZ | B31: 2025-08-26 21:21:50.354000 UTC | C31: 2025-08-26T21:21:49.817Z | D31: 2025-08-26 21:21:55.000000 UTC | E31: 2025-08-26 21:21:56.000000 UTC | G31: jp | H31: FALSE | I31: FALSE | K31: 4.646 | L31: 1 | M31: 5.646
A32: okta_463c6f30-b140-4374-9a3d-d44f88a78203 | B32: 2025-08-26 09:02:06.383000 UTC | C32: 2025-08-26T09:02:05.860Z | D32: 2025-08-26 09:02:11.000000 UTC | E32: 2025-08-26 09:02:17.000000 UTC | G32: jp | H32: FALSE | I32: FALSE | K32: 4.617 | L32: 6 | M32: 10.617
A33: okta_3802850b-ff58-4b51-b9bc-6d87b6aa9cac | B33: 2025-08-25 09:09:02.401000 UTC | C33: 2025-08-25T09:09:01.834Z | D33: 2025-08-25 09:09:07.000000 UTC | E33: 2025-08-25 09:09:09.000000 UTC | G33: jp | H33: FALSE | I33: FALSE | K33: 4.599 | L33: 2 | M33: 6.599
A34: okta_6c989e2d-1e7d-4293-8cdf-ca99746383a4 | B34: 2025-08-26 15:07:31.486000 UTC | C34: 2025-08-26T15:07:30.943Z | D34: 2025-08-26 15:07:36.000000 UTC | E34: 2025-08-26 15:07:40.000000 UTC | G34: jp | H34: FALSE | I34: FALSE | K34: 4.514 | L34: 4 | M34: 8.514
A35: okta_2918a692-45a4-46c5-8c36-772b653d7001 | B35: 2025-08-26 13:36:11.489000 UTC | C35: 2025-08-26T13:36:10.951Z | D35: 2025-08-26 13:36:16.000000 UTC | E35: 2025-08-26 13:36:18.000000 UTC | G35: jp | H35: FALSE | I35: FALSE | K35: 4.511 | L35: 2 | M35: 6.511
A36: okta_f5862d89-3fa8-46c2-afae-0f63b4ecfdd1 | B36: 2025-08-26 06:00:15.491000 UTC | C36: 2025-08-26T06:00:14.936Z | D36: 2025-08-26 06:00:20.000000 UTC | E36: 2025-08-26 06:00:22.000000 UTC | G36: jp | H36: FALSE | I36: FALSE | K36: 4.509 | L36: 2 | M36: 6.509
A37: okta_47f11e30-512d-4ef6-82d4-825dd2ad3923 | B37: 2025-08-26 22:43:12.504000 UTC | C37: 2025-08-26T22:43:12.010Z | D37: 2025-08-26 22:43:17.000000 UTC | E37: 2025-08-26 22:43:18.000000 UTC | G37: jp | H37: FALSE | I37: FALSE | K37: 4.496 | L37: 1 | M37: 5.496
A38: okta_a2cd2bfc-0d1a-49e5-a2a4-6ea08d99894b | B38: 2025-08-25 11:29:21.527000 UTC | C38: 2025-08-25T11:29:20.809Z | D38: 2025-08-25 11:29:26.000000 UTC | E38: 2025-08-25 11:29:27.000000 UTC | G38: jp | H38: FALSE | I38: FALSE | K38: 4.473 | L38: 1 | M38: 5.473
A39: okta_8da82a24-61f7-4d30-ac68-a6ed8877923b | B39: 2025-08-25 08:21:43.530000 UTC | C39: 2025-08-25T08:21:43.102Z | D39: 2025-08-25 08:21:48.000000 UTC | E39: 2025-08-25 08:21:50.000000 UTC | G39: jp | H39: FALSE | I39: FALSE | K39: 4.47 | L39: 2 | M39: 6.47
A40: okta_9ae1224b-549b-4d22-8668-462eccf3f7bc | B40: 2025-08-25 09:02:44.543000 UTC | C40: 2025-08-25T09:02:44.063Z | D40: 2025-08-25 09:02:49.000000 UTC | E40: 2025-08-25 09:02:55.000000 UTC | G40: jp | H40: FALSE | I40: FALSE | K40: 4.457 | L40: 6 | M40: 10.457
...

Sheet bounce data
A1: EXTERNAL_USER_ID | B1: country_code | C1: BOUNCE_REASON | D1: REASON
A2: JR8n4YDBTU2Q | B2: PT | C2: 554 5.4.14 Hop count exceeded - possible mail loop ATTR34 [BN3PEPF0000B373.namprd21.prod.outlook.com 2025-09-18T13:19:17.521Z 08DDF24801AC6EA9] | D2: SOFT_BOUNCE
A3: okta_b93c7eb3-0727-405a-b568-fd485415c348 | B3: IN | C3: 452 4.2.2 The recipient's inbox is out of storage space. Please direct the recipient to https://support.google.com/mail/?p=OverQuotaTemp af79cd13be357-7e82d870259si622307485a.930 - gsmtp | D3: SOFT_BOUNCE
A4: okta_b93c7eb3-0727-405a-b568-fd485415c348 | B4: IN | C4: 452 4.2.2 The recipient's inbox is out of storage space. Please direct the recipient to https://support.google.com/mail/?p=OverQuotaTemp ca18e2360f4ac-883f1a21334si1925561639f.197 - gsmtp | D4: SOFT_BOUNCE
A5: JR171EDJSPXF | B5: JP | C5: 554 Message not allowed - SGS Email not accepted for policy reasons. Please visit https://support.yahoo-net.jp/PccMail/s/article/H000007355[916] | D5: SOFT_BOUNCE
A6: okta_b93c7eb3-0727-405a-b568-fd485415c348 | B6: IN | C6: 452 4.2.2 The recipient's inbox is out of storage space. Please direct the recipient to https://support.google.com/mail/?p=OverQuotaTemp 41be03b00d2f7-b4746d89ec8si482954a12.730 - gsmtp | D6: SOFT_BOUNCE
A7: JR8n4YDBTU2Q | B7: PT | C7: 554 5.4.14 Hop count exceeded - possible mail loop ATTR34 [DS3PEPF000099D9.namprd04.prod.outlook.com 2025-08-25T20:42:53.446Z 08DDE2494C67D5AE] | D7: SOFT_BOUNCE
A8: JR8n4YDBTU2Q | B8: PT | C8: 554 5.4.14 Hop count exceeded - possible mail loop ATTR34 [BN3PEPF0000B077.namprd04.prod.outlook.com 2025-08-25T20:37:23.009Z 08DDE27A6C4098DE] | D8: SOFT_BOUNCE
A9: JR8n4YDBTU2Q | B9: PT | C9: 554 5.4.14 Hop count exceeded - possible mail loop ATTR34 [CH2PEPF0000013F.namprd02.prod.outlook.com 2025-08-26T07:00:34.687Z 08DDE04FA989DB2F] | D9: SOFT_BOUNCE
A10: okta_faa9f414-1632-4836-9b35-f981942caffb | B10: IN | C10: 452 4.2.2 The recipient's inbox is out of storage space. Please direct the recipient to https://support.google.com/mail/?p=OverQuotaTemp 6a1803df08f44-878bae61e35si6800156d6.243 - gsmtp | D10: SOFT_BOUNCE
A11: JR8n4YDBTU2Q | B11: PT | C11: 554 5.4.14 Hop count exceeded - possible mail loop ATTR34 [CY4PEPF0000E9D9.namprd05.prod.outlook.com 2025-09-18T13:18:09.027Z 08DDF47B7F63E847] | D11: SOFT_BOUNCE
A12: JR8n4YDBTU2Q | B12: PT | C12: 554 5.4.14 Hop count exceeded - possible mail loop ATTR34 [DS1PEPF0001709C.namprd05.prod.outlook.com 2025-09-18T13:17:36.550Z 08DDF41E6973826F] | D12: SOFT_BOUNCE
... A29: PC28519729 | B29: JP | C29: 550 Unknown user a-i309@docomo.ne.jp | D29: HARD_BOUNCE
A30: 104714598 | B30: JP | C30: 550 Unknown user to-.-hyy@docomo.ne.jp | D30: HARD_BOUNCE
A31: 104714598 | B31: JP | C31: 550 Unknown user to-.-hyy@docomo.ne.jp | D31: HARD_BOUNCE
A32: 20735018 | B32: JP | C32: 550 Unknown user choco_e.snow_1442@docomo.ne.jp | D32: HARD_BOUNCE
A33: 20735018 | B33: JP | C33: 550 Unknown user choco_e.snow_1442@docomo.ne.jp | D33: HARD_BOUNCE
A34: okta_727825c1-11e2-41a4-8cde-3713af47e68a | B34: IN | C34: 550 5.1.1 The email account that you tried to reach does not exist. Please try double-checking the recipient's email address for typos or unnecessary spaces. For more information, go to https://support.google.com/mail/?p=NoSuchUser 6a1803df08f44-70da73356c7si6906556d6.862 - gsmtp | D34: HARD_BOUNCE
A35: okta_5e022581-9f54-46bb-aae8-56757253dffa | B35: IN | C35: 550 5.1.1 The email account that you tried to reach does not exist. Please try double-checking the recipient's email address for typos or unnecessary spaces. For more information, go to https://support.google.com/mail/?p=NoSuchUser e9e14a558f8ab-3ea4bfa0408si47257525ab.51 - gsmtp | D35: HARD_BOUNCE
A36: okta_f7de2d13-aec1-41a7-a17f-100810622666 | B36: JP | C36: 550 5.1.1 The email account that you tried to reach does not exist. Please try double-checking the recipient's email address for typos or unnecessary spaces. For more information, go to https://support.google.com/mail/?p=NoSuchUser af79cd13be357-7ebf1bc3a42si73527085a.629 - gsmtp | D36: HARD_BOUNCE
A37: okta_d6b177b6-4c3c-4aab-995c-87802722e5a8 | B37: IN | C37: 550 5.1.1 The email account that you tried to reach does not exist. Please try double-checking the recipient's email address for typos or unnecessary spaces. For more information, go to https://support.google.com/mail/?p=NoSuchUser ca18e2360f4ac-886c903e3desi625013239f.169 - gsmtp | D37: HARD_BOUNCE
A38: okta_81893c27-c2d5-40a2-bca3-5767593653f5 | B38: IN | C38: 511 sorry, no mailbox here by that name (#5.1.1 - chkuser) | D38: HARD_BOUNCE
A39: okta_2b4ed77f-ade9-4707-8b8d-9b97429d7a90 | B39: IN | C39: 550 5.1.1 The email account that you tried to reach does not exist. Please try double-checking the recipient's email address for typos or unnecessary spaces. For more information, go to https://support.google.com/mail/?p=NoSuchUser e9e14a558f8ab-3ea4f1ed0dcsi67879245ab.216 - gsmtp | D39: HARD_BOUNCE
A40: okta_81893c27-c2d5-40a2-bca3-5767593653f5 | B40: IN | C40: 511 sorry, no mailbox here by that name (#5.1.1 - chkuser) | D40: HARD_BOUNCE
A41: okta_3356aa1c-6754-48c8-a6c2-80a3e738d49e | B41: RO | C41: 550 5.1.1 <pievuana89@icloud.com>: user does not exist | D41: HARD_BOUNCE
A42: okta_6f539eaf-3b9e-45eb-8a00-0553b2125991 | B42: US | C42: 552 1 Requested mail action aborted, mailbox not found | D42: HARD_BOUNCE
A43: JR172FDFJTZI | B43: JP | D43: EMAIL_SENT
A44: okta_d9fa3afb-b536-4cad-9d9c-3d88e2debe02 | B44: IN | D44: EMAIL_SENT
A45: okta_d9fa3afb-b536-4cad-9d9c-3d88e2debe02 | B45: IN | D45: EMAIL_SENT
A46: okta_d9fa3afb-b536-4cad-9d9c-3d88e2debe02 | B46: IN | D46: EMAIL_SENT
A47: JR17386SWNB8 | D47: EMAIL_SENT
A48: JR17386SWNB8 | D48: EMAIL_SENT
A49: okta_b93c7eb3-0727-405a-b568-fd485415c348 | B49: IN | D49: EMAIL_SENT
A50: okta_b93c7eb3-0727-405a-b568-fd485415c348 | B50: IN | D50: EMAIL_SENT
A51: JR171EDJSPXF | D51: EMAIL_SENT
A52: JR171EDJSPXF | D52: EMAIL_SENT
A53: okta_ee4cc802-cec3-4f78-85df-b26f58ae69f6 | B53: IN | D53: EMAIL_SENT
A54: okta_b93c7eb3-0727-405a-b568-fd485415c348 | B54: IN | D54: EMAIL_SENT
A55: okta_b93c7eb3-0727-405a-b568-fd485415c348 | B55: IN | D55: EMAIL_SENT
A56: okta_21850105-ab5b-48c3-a42b-7ec640ac05a8 | B56: IN | D56: EMAIL_SENT
...

Sheet available in braze
A1: user_id | B1: Country_code | C1: data available | D1: notes | E1: available between 23-27 | F1: comments based on 23-27th Aug | G1: available in bounce/reason | H1: REASON
A2: okta_2b4ed77f-ade9-4707-8b8d-9b97429d7a90 | B2: in | C2: No | D2: email bounced on 24th | E2: =VLOOKUP(A2,'23-27'!$A:$D,3,FALSE) -> Campaign Converted | F2: email sent and bounced on 24th | G2: =VLOOKUP(A2,'bounce data'!$A:$C,3,FALSE) -> 550 5.1.1 The email account that you tried to reach does not exist. Please try double-checking the recipient's email address for typos or unnecessary spaces. For more information, go to https://support.google.com/mail/?p=NoSuchUser e9e14a558f8ab-3ea4f1ed0dcsi67879245ab.216 - gsmtp | H2: =VLOOKUP(A2,'bounce data'!A:D,4,FALSE) -> HARD_BOUNCE
A3: okta_0d7f7255-6dad-4ebd-bec3-1111576a9aa1 | B3: in | C3: No | E3: =VLOOKUP(A3,'23-27'!$A:$D,3,FALSE) -> #N/A | F3: email sent and delivered on 25th | H3: =VLOOKUP(A3,'bounce data'!A:D,4,FALSE) -> #N/A
A4: okta_5e022581-9f54-46bb-aae8-56757253dffa | B4: in | C4: No | E4: =VLOOKUP(A4,'23-27'!$A:$D,3,FALSE) -> Campaign Converted | F4: email sent and bounced on 23rd | G4: =VLOOKUP(A4,'bounce data'!$A:$C,3,FALSE) -> 550 5.1.1 The email account that you tried to reach does not exist. Please try double-checking the recipient's email address for typos or unnecessary spaces. For more information, go to https://support.google.com/mail/?p=NoSuchUser e9e14a558f8ab-3ea4bfa0408si47257525ab.51 - gsmtp | H4: =VLOOKUP(A4,'bounce data'!A:D,4,FALSE) -> HARD_BOUNCE
A5: okta_6f539eaf-3b9e-45eb-8a00-0553b2125991 | B5: in | C5: No | D5: email bounced on 24th | E5: =VLOOKUP(A5,'23-27'!$A:$D,3,FALSE) -> Campaign Converted | F5: email send and bounced on 24th | G5: =VLOOKUP(A5,'bounce data'!$A:$C,3,FALSE) -> 552 1 Requested mail action aborted, mailbox not found | H5: =VLOOKUP(A5,'bounce data'!A:D,4,FALSE) -> HARD_BOUNCE
A6: okta_727825c1-11e2-41a4-8cde-3713af47e68a | B6: in | C6: No | E6: =VLOOKUP(A6,'23-27'!$A:$D,3,FALSE) -> Campaign Converted | F6: email sent and bounced on 23rd | G6: =VLOOKUP(A6,'bounce data'!$A:$C,3,FALSE) -> 550 5.1.1 The email account that you tried to reach does not exist. Please try double-checking the recipient's email address for typos or unnecessary spaces. For more information, go to https://support.google.com/mail/?p=NoSuchUser 6a1803df08f44-70da73356c7si6906556d6.862 - gsmtp | H6: =VLOOKUP(A6,'bounce data'!A:D,4,FALSE) -> HARD_BOUNCE
A7: okta_81893c27-c2d5-40a2-bca3-5767593653f5 | B7: in | C7: No | D7: email bounced on 24th | E7: =VLOOKUP(A7,'23-27'!$A:$D,3,FALSE) -> Campaign Converted | F7: email sent and bounced on 24th | G7: =VLOOKUP(A7,'bounce data'!$A:$C,3,FALSE) -> 511 sorry, no mailbox here by that name (#5.1.1 - chkuser) | H7: =VLOOKUP(A7,'bounce data'!A:D,4,FALSE) -> HARD_BOUNCE
A8: okta_d6b177b6-4c3c-4aab-995c-87802722e5a8 | B8: in | C8: No | D8: email bounced on 24th | E8: =VLOOKUP(A8,'23-27'!$A:$D,3,FALSE) -> Campaign Converted | F8: email sent and bounced on 24th | G8: =VLOOKUP(A8,'bounce data'!$A:$C,3,FALSE) -> 550 5.1.1 The email account that you tried to reach does not exist. Please try double-checking the recipient's email address for typos or unnecessary spaces. For more information, go to https://support.google.com/mail/?p=NoSuchUser ca18e2360f4ac-886c903e3desi625013239f.169 - gsmtp | H8: =VLOOKUP(A8,'bounce data'!A:D,4,FALSE) -> HARD_BOUNCE
A9: okta_3356aa1c-6754-48c8-a6c2-80a3e738d49e | B9: ro | C9: No | D9: email sent and bounced on 24th | E9: =VLOOKUP(A9,'23-27'!$A:$D,3,FALSE) -> Campaign Converted | F9: email sent and bounced on 24th | G9: =VLOOKUP(A9,'bounce data'!$A:$C,3,FALSE) -> 550 5.1.1 <pievuana89@icloud.com>: user does not exist | H9: =VLOOKUP(A9,'bounce data'!A:D,4,FALSE) -> HARD_BOUNCE
A10: 20735018 | B10: jp | C10: No | D10: received otp next day | E10: =VLOOKUP(A10,'23-27'!$A:$D,3,FALSE) -> Campaign Converted | F10: email sent and delivered on 27th | G10: =VLOOKUP(A10,'bounce data'!$A:$C,3,FALSE) -> 550 Unknown user choco_e.snow_1442@docomo.ne.jp | H10: =VLOOKUP(A10,'bounce data'!A:D,4,FALSE) -> HARD_BOUNCE
A11: okta_f7de2d13-aec1-41a7-a17f-100810622666 | B11: jp | C11: No | E11: =VLOOKUP(A11,'23-27'!$A:$D,3,FALSE) -> Campaign Converted | F11: email sent and bounced on 23rd | G11: =VLOOKUP(A11,'bounce data'!$A:$C,3,FALSE) -> 550 5.1.1 The email account that you tried to reach does not exist. Please try double-checking the recipient's email address for typos or unnecessary spaces. For more information, go to https://support.google.com/mail/?p=NoSuchUser af79cd13be357-7ebf1bc3a42si73527085a.629 - gsmtp | H11: =VLOOKUP(A11,'bounce data'!A:D,4,FALSE) -> HARD_BOUNCE
A12: okta_0ee80899-1be8-4f0c-be0b-599302ce9474 | B12: in | C12: No | E12: =VLOOKUP(A12,'23-27'!$A:$D,3,FALSE) -> Email Sent | F12: email sent and delivered on 25th | H12: =VLOOKUP(A12,'bounce data'!A:D,4,FALSE) -> #N/A
A13: okta_0ee80899-1be8-4f0c-be0b-599302ce9474 | B13: in | C13: No | E13: =VLOOKUP(A13,'23-27'!$A:$D,3,FALSE) -> Email Sent | F13: email sent and delivered on 26th | G13: =VLOOKUP(A13,'bounce data'!$A:$C,3,FALSE) -> #N/A | H13: =VLOOKUP(A13,'bounce data'!A:D,4,FALSE) -> #N/A
A14: okta_0ee80899-1be8-4f0c-be0b-599302ce9474 | B14: in | C14: No | E14: =VLOOKUP(A14,'23-27'!$A:$D,3,FALSE) -> Email Sent | F14: email sent and delivered on 26th | G14: =VLOOKUP(A14,'bounce data'!$A:$C,3,FALSE) -> #N/A | H14: =VLOOKUP(A14,'bounce data'!A:D,4,FALSE) -> #N/A
A15: PC5219056 | B15: jp | C15: No | D15: received otp next day | E15: =VLOOKUP(A15,'23-27'!$A:$D,3,FALSE) -> Email Sent | F15: email sent and delivered on 27th | G15: =VLOOKUP(A15,'bounce data'!$A:$C,3,FALSE) -> 550 Unknown user kuroron3-tomcat.2300@docomo.ne.jp | H15: =VLOOKUP(A15,'bounce data'!A:D,4,FALSE) -> HARD_BOUNCE
A16: JR1b40ER45YH | B16: in | C16: No | E16: =VLOOKUP(A16,'23-27'!$A:$D,3,FALSE) -> #N/A | G16: =VLOOKUP(A16,'bounce data'!$A:$C,3,FALSE) -> #N/A | H16: =VLOOKUP(A16,'bounce data'!A:D,4,FALSE) -> #N/A
A17: okta_21850105-ab5b-48c3-a42b-7ec640ac05a8 | B17: in | C17: No | E17: =VLOOKUP(A17,'23-27'!$A:$D,3,FALSE) -> #N/A | G17: =VLOOKUP(A17,'bounce data'!$A:$C,3,FALSE) -> 511 sorry, no mailbox here by that name (#5.1.1 - chkuser) | H17: =VLOOKUP(A17,'bounce data'!A:D,4,FALSE) -> HARD_BOUNCE
A18: okta_3302a291-a29d-4628-94a8-1818b3ddcf0a | B18: in | C18: No | E18: =VLOOKUP(A18,'23-27'!$A:$D,3,FALSE) -> #N/A | G18: =VLOOKUP(A18,'bounce data'!$A:$C,3,FALSE) -> #N/A | H18: =VLOOKUP(A18,'bounce data'!A:D,4,FALSE) -> #N/A
A19: okta_99f4fd4a-8ee3-450a-a479-f559891bf0dc | B19: in | C19: No | E19: =VLOOKUP(A19,'23-27'!$A:$D,3,FALSE) -> Email Opened | F19: email sent and delivered on 25th | H19: =VLOOKUP(A19,'bounce data'!A:D,4,FALSE) -> #N/A
A20: okta_34d506fe-200f-49c2-9690-69293db17c5f | B20: in | C20: No | E20: =VLOOKUP(A20,'23-27'!$A:$D,3,FALSE) -> #N/A | G20: =VLOOKUP(A20,'bounce data'!$A:$C,3,FALSE) -> #N/A | H20: =VLOOKUP(A20,'bounce data'!A:D,4,FALSE) -> #N/A
A21: okta_3f02c301-1884-48ce-9733-c98b006614c2 | B21: in | C21: No | E21: =VLOOKUP(A21,'23-27'!$A:$D,3,FALSE) -> #N/A | G21: =VLOOKUP(A21,'bounce data'!$A:$C,3,FALSE) -> #N/A | H21: =VLOOKUP(A21,'bounce data'!A:D,4,FALSE) -> #N/A
A22: okta_6f6e4c06-eeb9-42aa-a9e8-7b9340ce17b7 | B22: in | C22: No | E22: =VLOOKUP(A22,'23-27'!$A:$D,3,FALSE) -> #N/A | G22: =VLOOKUP(A22,'bounce data'!$A:$C,3,FALSE) -> 0 | H22: =VLOOKUP(A22,'bounce data'!A:D,4,FALSE) -> EMAIL_SENT
A23: okta_832464e5-e057-4c3d-a1bf-e2d1a28b08df | B23: in | C23: No | E23: =VLOOKUP(A23,'23-27'!$A:$D,3,FALSE) -> #N/A | G23: =VLOOKUP(A23,'bounce data'!$A:$C,3,FALSE) -> 0 | H23: =VLOOKUP(A23,'bounce data'!A:D,4,FALSE) -> EMAIL_SENT
A24: okta_8e73f429-3f56-42f1-87c8-357a1ac444d2 | B24: in | C24: No | E24: =VLOOKUP(A24,'23-27'!$A:$D,3,FALSE) -> #N/A | G24: =VLOOKUP(A24,'bounce data'!$A:$C,3,FALSE) -> 511 sorry, no mailbox here by that name (#5.1.1 - chkuser) | H24: =VLOOKUP(A24,'bounce data'!A:D,4,FALSE) -> HARD_BOUNCE
A25: okta_976b5ded-6c74-49ab-a804-37c4c7c3ce87 | B25: in | C25: No | E25: =VLOOKUP(A25,'23-27'!$A:$D,3,FALSE) -> #N/A | G25: =VLOOKUP(A25,'bounce data'!$A:$C,3,FALSE) -> #N/A | H25: =VLOOKUP(A25,'bounce data'!A:D,4,FALSE) -> #N/A
A26: okta_b93c7eb3-0727-405a-b568-fd485415c348 | B26: in | C26: No | E26: =VLOOKUP(A26,'23-27'!$A:$D,3,FALSE) -> #N/A | G26: =VLOOKUP(A26,'bounce data'!$A:$C,3,FALSE) -> 452 4.2.2 The recipient's inbox is out of storage space. Please direct the recipient to https://support.google.com/mail/?p=OverQuotaTemp af79cd13be357-7e82d870259si622307485a.930 - gsmtp | H26: =VLOOKUP(A26,'bounce data'!A:D,4,FALSE) -> SOFT_BOUNCE
A27: okta_d4d8a608-1866-4283-8264-40cbca447176 | B27: in | C27: No | E27: =VLOOKUP(A27,'23-27'!$A:$D,3,FALSE) -> #N/A | G27: =VLOOKUP(A27,'bounce data'!$A:$C,3,FALSE) -> #N/A | H27: =VLOOKUP(A27,'bounce data'!A:D,4,FALSE) -> #N/A
A28: okta_d9fa3afb-b536-4cad-9d9c-3d88e2debe02 | B28: in | C28: No | E28: =VLOOKUP(A28,'23-27'!$A:$D,3,FALSE) -> #N/A | G28: =VLOOKUP(A28,'bounce data'!$A:$C,3,FALSE) -> error dialing remote address: dial tcp 149.72.42.7:0->198.49.23.144:25: i/o timeout | H28: =VLOOKUP(A28,'bounce data'!A:D,4,FALSE) -> SOFT_BOUNCE
A29: okta_ed24e51b-2e72-4ab0-82de-f1ab0e137b8b | B29: in | C29: No | E29: =VLOOKUP(A29,'23-27'!$A:$D,3,FALSE) -> #N/A | G29: =VLOOKUP(A29,'bounce data'!$A:$C,3,FALSE) -> #N/A | H29: =VLOOKUP(A29,'bounce data'!A:D,4,FALSE) -> #N/A
A30: okta_ee4cc802-cec3-4f78-85df-b26f58ae69f6 | B30: in | C30: No | E30: =VLOOKUP(A30,'23-27'!$A:$D,3,FALSE) -> #N/A | G30: =VLOOKUP(A30,'bounce data'!$A:$C,3,FALSE) -> 550 5.1.1 The email account that you tried to reach does not exist. Please try double-checking the recipient's email address for typos or unnecessary spaces. For more information, go to https://support.google.com/mail/?p=NoSuchUser 8926c6da1cb9f-50c94beb676si4814725173.220 - gsmtp | H30: =VLOOKUP(A30,'bounce data'!A:D,4,FALSE) -> HARD_BOUNCE
A31: okta_faa9f414-1632-4836-9b35-f981942caffb | B31: in | C31: No | E31: =VLOOKUP(A31,'23-27'!$A:$D,3,FALSE) -> #N/A | G31: =VLOOKUP(A31,'bounce data'!$A:$C,3,FALSE) -> 452 4.2.2 The recipient's inbox is out of storage space. Please direct the recipient to https://support.google.com/mail/?p=OverQuotaTemp 6a1803df08f44-878bae61e35si6800156d6.243 - gsmtp | H31: =VLOOKUP(A31,'bounce data'!A:D,4,FALSE) -> SOFT_BOUNCE
A32: JR8n3W65SR0E | B32: pt | C32: No | D32: no data before or after date range | E32: =VLOOKUP(A32,'23-27'!$A:$D,3,FALSE) -> #N/A | G32: =VLOOKUP(A32,'bounce data'!$A:$C,3,FALSE) -> #N/A | H32: =VLOOKUP(A32,'bounce data'!A:D,4,FALSE) -> #N/A
A33: JR8n469E5EWA | B33: pt | C33: No | E33: =VLOOKUP(A33,'23-27'!$A:$D,3,FALSE) -> #N/A | G33: =VLOOKUP(A33,'bounce data'!$A:$C,3,FALSE) -> #N/A | H33: =VLOOKUP(A33,'bounce data'!A:D,4,FALSE) -> #N/A
A34: JR8n4IZZWGZG | B34: pt | C34: No | E34: =VLOOKUP(A34,'23-27'!$A:$D,3,FALSE) -> #N/A | G34: =VLOOKUP(A34,'bounce data'!$A:$C,3,FALSE) -> #N/A | H34: =VLOOKUP(A34,'bounce data'!A:D,4,FALSE) -> #N/A
A35: JR8n4YDBTU2Q | B35: pt | C35: No | E35: =VLOOKUP(A35,'23-27'!$A:$D,3,FALSE) -> #N/A | G35: =VLOOKUP(A35,'bounce data'!$A:$C,3,FALSE) -> 554 5.4.14 Hop count exceeded - possible mail loop ATTR34 [BN3PEPF0000B373.namprd21.prod.outlook.com 2025-09-18T13:19:17.521Z 08DDF24801AC6EA9] | H35: =VLOOKUP(A35,'bounce data'!A:D,4,FALSE) -> SOFT_BOUNCE
A36: okta_1f6a95e5-ea61-4c8c-816e-bdfe325382dd | B36: pt | C36: No | E36: =VLOOKUP(A36,'23-27'!$A:$D,3,FALSE) -> #N/A | G36: =VLOOKUP(A36,'bounce data'!$A:$C,3,FALSE) -> 0 | H36: =VLOOKUP(A36,'bounce data'!A:D,4,FALSE) -> EMAIL_SENT
A37: okta_a951bac4-278e-4a97-be37-0b3d6daa345e | B37: pt | C37: No | E37: =VLOOKUP(A37,'23-27'!$A:$D,3,FALSE) -> #N/A | G37: =VLOOKUP(A37,'bounce data'!$A:$C,3,FALSE) -> #N/A | H37: =VLOOKUP(A37,'bounce data'!A:D,4,FALSE) -> #N/A
A38: okta_46a394e0-8e98-4962-8086-79f71a77b9ed | B38: ro | C38: No | E38: =VLOOKUP(A38,'23-27'!$A:$D,3,FALSE) -> #N/A | G38: =VLOOKUP(A38,'bounce data'!$A:$C,3,FALSE) -> #N/A | H38: =VLOOKUP(A38,'bounce data'!A:D,4,FALSE) -> #N/A
A39: okta_72f92a60-f221-4900-b3df-dae8bc08de60 | B39: ro | C39: No | E39: =VLOOKUP(A39,'23-27'!$A:$D,3,FALSE) -> #N/A | G39: =VLOOKUP(A39,'bounce data'!$A:$C,3,FALSE) -> #N/A | H39: =VLOOKUP(A39,'bounce data'!A:D,4,FALSE) -> #N/A
A40: okta_78020c6a-461a-4028-86b5-3c19a637f5b7 | B40: ro | C40: No | E40: =VLOOKUP(A40,'23-27'!$A:$D,3,FALSE) -> #N/A | G40: =VLOOKUP(A40,'bounce data'!$A:$C,3,FALSE) -> #N/A | H40: =VLOOKUP(A40,'bounce data'!A:D,4,FALSE) -> #N/A
...

Sheet summary
A1: Market | B1: 2FA exposed | C1: Backend: Code Not Sent | D1: Braze CLT: Event Missing | E1: Braze Dumps: Event Found | F1: Email Sent | G1: Incorrect Email | H1: Unknown Error
A2: JP | B2: 1731 | C2: 40 | D2: 24 | E2: 15 | F2: =B2-SUM(C2:D2) -> 1667 | G2: 7 | H2: 11
A3: IN | B3: 824 | C3: 7 | D3: 27 | E3: 15 | F3: =B3-SUM(C3:D3) -> 790 | G3: 12 | H3: 9
A4: PT | B4: 282 | C4: 13 | D4: 13 | E4: 2 | F4: =B4-SUM(C4:D4) -> 256 | G4: 1 | H4: 4
A5: RO | B5: 357 | C5: 30 | D5: 4 | E5: 1 | F5: =B5-SUM(C5:D5) -> 323 | G5: 1 | H5: 3
B9: Markets | C9: JP | D9: IN | E9: PT | F9: RO | G9: Notes | H9: Suggestion/Recos
B10: 2FA Exposed | C10: 1 | D10: 1 | E10: 1 | F10: 1
B11: Email Sent Successfully | C11: 0.99 | D11: 0.9745 | E11: 0.9823 | F11: 0.9888
B12: Incorrect Email/Email Bounced | C12: =(G2/B2) -> 0.0040439053 | D12: =G3/B3 -> 0.014563107 | E12: =G4/B4 -> 0.0035460993 | F12: =G5/B5 -> 0.0028011204 | G12: Email ID had invalid characters, inbox not found, storage full | H12: 1. Make email ID visible on 2FA screen. 2. Let user change email from 2FA incase if he finds his email to be incorrect.
B13: Unknown Error (Data Unavailable) | C13: =H2/B2 -> 0.0063547083 | D13: =H3/B3 -> 0.01092233 | E13: =H4/B4 -> 0.014184397 | F13: =H5/B5 -> 0.0084033613
B15: Delivery Rate | C15: 0.986 | D15: 0.905 | E15: 0.992 | F15: 0.978
B17: 2fa Exposed to Email sent: Avg time | C17: 1.8 sec | D17: 0.42 sec | E17: 2.18 sec | F17: 1.51 sec

Sheet 23-27
A1: user_id | B1: country_code | C1: braze_event_name | D1: braze_timestamp
A2: 20735018 | B2: jp | C2: Campaign Converted | D2: 2025-08-23 23:57:47.000000 UTC
A3: 20735018 | B3: jp | C3: Email Bounced | D3: 2025-08-23 23:51:07.000000 UTC
A4: 20735018 | B4: jp | C4: Email Sent | D4: 2025-08-23 23:51:05.000000 UTC
A5: 20735018 | B5: jp | C5: Email Sent | D5: 2025-08-27 00:30:18.000000 UTC
A6: 20735018 | B6: jp | C6: Email Opened | D6: 2025-08-27 00:30:38.000000 UTC
A7: 20735018 | B7: jp | C7: Email Delivered | D7: 2025-08-27 00:30:19.000000 UTC
A8: 20735018 | B8: jp | C8: Campaign Converted | D8: 2025-08-27 00:30:51.000000 UTC
A9: PC5219056 | B9: jp | C9: Email Sent | D9: 2025-08-27 12:27:13.000000 UTC
A10: PC5219056 | B10: jp | C10: Email Opened | D10: 2025-08-27 12:28:08.000000 UTC
A11: PC5219056 | B11: jp | C11: Email Opened | D11: 2025-08-27 12:27:29.000000 UTC
A12: PC5219056 | B12: jp | C12: Email Delivered | D12: 2025-08-27 12:27:15.000000 UTC
A13: PC5219056 | B13: jp | C13: Campaign Converted | D13: 2025-08-27 12:28:20.000000 UTC
A14: okta_0ee80899-1be8-4f0c-be0b-599302ce9474 | C14: Email Sent | D14: 2025-08-25 18:01:41.000000 UTC
A15: okta_0ee80899-1be8-4f0c-be0b-599302ce9474 | C15: Email Delivered | D15: 2025-08-25 18:01:47.000000 UTC
A16: okta_0ee80899-1be8-4f0c-be0b-599302ce9474 | C16: Email Machine Opened | D16: 2025-08-26 11:44:17.000000 UTC
A17: okta_0ee80899-1be8-4f0c-be0b-599302ce9474 | C17: Email Opened | D17: 2025-08-25 18:01:58.000000 UTC
A18: okta_0ee80899-1be8-4f0c-be0b-599302ce9474 | C18: Campaign Converted | D18: 2025-08-25 18:02:03.000000 UTC
A19: okta_2b4ed77f-ade9-4707-8b8d-9b97429d7a90 | B19: in | C19: Campaign Converted | D19: 2025-08-24 07:43:15.000000 UTC
A20: okta_2b4ed77f-ade9-4707-8b8d-9b97429d7a90 | B20: in | C20: Email Bounced | D20: 2025-08-24 07:42:30.000000 UTC
A21: okta_2b4ed77f-ade9-4707-8b8d-9b97429d7a90 | B21: in | C21: Email Sent | D21: 2025-08-24 07:42:29.000000 UTC
A22: okta_3356aa1c-6754-48c8-a6c2-80a3e738d49e | B22: ro | C22: Campaign Converted | D22: 2025-08-24 22:50:52.000000 UTC
A23: okta_3356aa1c-6754-48c8-a6c2-80a3e738d49e | B23: ro | C23: Email Bounced | D23: 2025-08-24 22:50:22.000000 UTC
A24: okta_3356aa1c-6754-48c8-a6c2-80a3e738d49e | B24: ro | C24: Email Sent | D24: 2025-08-24 22:50:20.000000 UTC
A25: okta_40ddf15c-edfe-4000-840c-81c190a405c7 | C25: Email Sent | D25: 2025-08-26 16:59:36.000000 UTC
A26: okta_40ddf15c-edfe-4000-840c-81c190a405c7 | C26: Email Sent | D26: 2025-08-26 17:08:06.000000 UTC
A27: okta_40ddf15c-edfe-4000-840c-81c190a405c7 | C27: Email Sent | D27: 2025-08-26 17:00:19.000000 UTC
A28: okta_40ddf15c-edfe-4000-840c-81c190a405c7 | C28: Email Opened | D28: 2025-08-27 03:24:49.000000 UTC
A29: okta_40ddf15c-edfe-4000-840c-81c190a405c7 | C29: Email Opened | D29: 2025-08-27 03:24:49.000000 UTC
A30: okta_40ddf15c-edfe-4000-840c-81c190a405c7 | C30: Email Opened | D30: 2025-08-27 03:24:49.000000 UTC
A31: okta_40ddf15c-edfe-4000-840c-81c190a405c7 | C31: Email Opened | D31: 2025-08-26 17:18:27.000000 UTC
A32: okta_40ddf15c-edfe-4000-840c-81c190a405c7 | C32: Email Opened | D32: 2025-08-26 17:00:48.000000 UTC
A33: okta_40ddf15c-edfe-4000-840c-81c190a405c7 | C33: Email Opened | D33: 2025-08-26 17:18:27.000000 UTC
A34: okta_40ddf15c-edfe-4000-840c-81c190a405c7 | C34: Email Opened | D34: 2025-08-26 17:18:27.000000 UTC
A35: okta_40ddf15c-edfe-4000-840c-81c190a405c7 | C35: Email Delivered | D35: 2025-08-26 17:00:23.000000 UTC
A36: okta_40ddf15c-edfe-4000-840c-81c190a405c7 | C36: Email Delivered | D36: 2025-08-26 17:08:07.000000 UTC
... A39: okta_40ddf15c-edfe-4000-840c-81c190a405c7 | C39: Campaign Converted | D39: 2025-08-27 03:25:05.000000 UTC
A40: okta_5e022581-9f54-46bb-aae8-56757253dffa | B40: in | C40: Campaign Converted | D40: 2025-08-23 16:46:46.000000 UTC
A41: okta_5e022581-9f54-46bb-aae8-56757253dffa | B41: in | C41: Email Bounced | D41: 2025-08-23 16:46:04.000000 UTC
